Workbook

Sheet PENDAPATAN
B2: PENDAPATAN 1 EKOR
B4: NO | C4: ITEMS | D4: HARGA JUAL | E4: QTY DALAM 1 EKOR | F4: PENDAPATAN PER EKOR
B5: 1 | C5: DADA | D5: 11000 | E5: 3 | F5: =PENDAPATAN!$D5*PENDAPATAN!$E5 -> 33000
B6: 2 | C6: PAHA ATAS | D6: =SUBTOTAL(109,D5) -> 11000 | E6: 2 | F6: =PENDAPATAN!$D6*PENDAPATAN!$E6 -> 22000
B7: 3 | C7: PAHA BAWAH | D7: 9000 | E7: 2 | F7: =PENDAPATAN!$D7*PENDAPATAN!$E7 -> 18000
B8: 4 | C8: SAYAP | D8: 8000 | E8: 2 | F8: =PENDAPATAN!$D8*PENDAPATAN!$E8 -> 16000
D9: TOTAL | E9: 9 | F9: =SUM(F5:F8) -> 89000
B12: NO | C12: ITEMS | D12: HARGA SATUAN | E12: HARGA PER EKOR | F12: KETERANGAN
B13: 1 | C13: AYAM/ EKOR | D13: 48000 | E13: 48000
B14: 2 | C14: TEPUNG/ PACK | D14: 23500 | E14: =PENDAPATAN!$D14/3 -> 7833.3333
B15: 3 | C15: KEMASAN/ PCS | D15: 23500 | E15: =PENDAPATAN!$D15/100*4.5 -> 1057.5
B16: 4 | C16: SAMBEL/ SACHET | D16: 22500 | E16: =PENDAPATAN!$D16/125*9 -> 1620
B17: 5 | C17: MINYAK GORENG/ 2LTR | D17: 37000 | E17: =PENDAPATAN!$D17/10 -> 3700
B18: 6 | C18: GAS/ 3 KG | D18: 23000 | E18: =PENDAPATAN!$D18/20 -> 1150
B19: 7 | C19: KANTONG PLASTIK/ PACK | D19: 7000 | E19: =PENDAPATAN!$D19/100*4 -> 280
D20: TOTAL HPP/ EKOR | E20: =E13+E14+E15+E16+E17+E18+E19 -> 63640.833
D21: PENDAPATAN/ EKOR | E21: 89000
D22: GROSS PROFIT/ EKOR | E22: =E21-E20 -> 25359.167

Sheet AYAM REGULER
C2: AYAM REGULER
C4: NO | D4: INGREDIENTS | E4: UOM | F4: BIAYA/UOM | G4: TOTAL COST/EKOR
C5: 1 | D5: Ayam Marinasi | E5: Ekor/9 Potong | F5: 48000 | G5: 48000
C6: 2 | D6: Tepung Bumbu | E6: Pack | F6: 23500 | G6: =F6/3 -> 7833.3333
C7: 3 | D7: Kantong Kemasan | E7: Ikat/ 100 | F7: 23500 | G7: =F7/100*4.5 -> 1057.5
C8: 4 | D8: Saus Sambal Delmonte | E8: Pack/ 125 Sachet | F8: 22500 | G8: =F8/125*9 -> 1620
C9: 5 | D9: Minyak Goreng | E9: Pouch/ 2 Liter | F9: 37700 | G9: =F9/10 -> 3770
C10: 6 | D10: Kantong Plastik | E10: Pack/ 50 Lembar | F10: 7000 | G10: =F10/50*2 -> 280
C11: 7 | D11: Gas 3 kg | E11: 3 Kg | F11: 23000 | G11: =F11/20 -> 1150
F12: Total Cost/ Ekor | G12: =SUM(G5:G11) -> 63710.833
F13: Pendapatan/ Ekor | G13: 89000
F14: Margin/ Ekor | G14: =G13-G12 -> 25289.167

Sheet AYAM SBP
B2: AYAM SBP
B4: NO | C4: INGREDIENTS | D4: UOM | E4: BIAYA/UOM | F4: TOTAL COST/EKOR
B5: 1 | C5: Ayam Marinasi | D5: Ekor/9 Potong | E5: 58000 | F5: =E5 -> 58000
B6: 2 | C6: Tepung Bumbu | D6: Pack | E6: 23500 | F6: =E6/3 -> 7833.3333
B7: 3 | C7: Kantong Kemasan | D7: Ikat/ 100 Lembar | E7: 23500 | F7: =E7/100*4.5 -> 1057.5
B8: 4 | C8: Saus Sambal Delmonte | D8: Pack/ 125 Sachet | E8: 22500 | F8: =E8/125*9 -> 1620
B9: 5 | C9: Minyak Goreng | D9: Pouch/ 2 Liter | E9: 37700 | F9: =E9/10 -> 3770
B10: 6 | C10: Kantong Plastik | D10: Pack/ 50 Lembar | E10: 7000 | F10: =E10/50*2 -> 280
B11: 7 | C11: Gas 3 kg | D11: 3 Kg | E11: 23000 | F11: =E11/20 -> 1150
E12: Total Cost/ Ekor | F12: =SUM(F5:F11) -> 73710.833
E13: Pendapatan/ Ekor | F13: 89000
E14: Margin/ Ekor | F14: =F13-F12 -> 15289.167

Sheet NASI
C2: NASI
C4: NO | D4: INGREDIENTS | E4: UOM | F4: BIAYA/UOM | G4: TOTAL COST/BUNGKUS
C5: 1 | D5: Beras Mentik Wangi | E5: 1liter | F5: 12000 | G5: =NASI!$F5/9 -> 1333.3333
C6: 2 | D6: Kertas Nasi | E6: Pack/100 | F6: 13000 | G6: =F6/100 -> 130
C7: 3 | D7: Box | E7: Pack/100 | F7: 125000 | G7: =NASI!$F7/100 -> 1250
F8: Total Cost/ Bungkus | G8: =G5+G6+G7 -> 2713.3333
F9: Pendapatan/ Bungkus | G9: 5000
F10: Margin/ Bungkus | G10: =G9-G8 -> 2286.6667
F11: Margin 2 Nasi | G11: =G10+G10 -> 4573.3333
F12: Harga Sosro 25ml | G12: 2500
F13: Margin Bundling | G13: =G11-G12 -> 2073.3333
C15: NO | D15: INGREDIENTS | E15: UOM | F15: BIAYA/UOM | G15: TOTAL COST/BUNGKUS
C16: 1 | D16: Beras Mentik Wangi | E16: 1liter | F16: 12000 | G16: =NASI!$F16/9 -> 1333.3333
C17: 2 | D17: Kertas Nasi | E17: Pack/100 | F17: 13000 | G17: =F17/100 -> 130
C18: 3 | D18: Kantong Kemasan Ayam | E18: Pack/100 | F18: 23500 | G18: =NASI!$F18/100 -> 235
F19: Total Cost/ Bungkus | G19: =G16+G17+G18 -> 1698.3333
F20: Pendapatan/ Bungkus | G20: 5000
F21: Margin/ Bungkus | G21: =G20-G19 -> 3301.6667

Sheet CR
B2: CHICKEN ROLL
B4: NO | C4: INGREDIENTS | D4: UOM | E4: BIAYA/UOM | F4: TOTAL COST/TUSUK
B5: 1 | C5: Chicken Roll | D5: Pack/ 10 Pcs | E5: 24400 | F5: =CR!$E5/10 -> 2440
B6: 2 | C6: Tepung Bumbu | D6: Pack | E6: 23500 | F6: =CR!$E6*0 -> 0
B7: 3 | C7: Minyak Goreng | D7: Pouch/ 2 Liter | E7: 37700 | F7: =CR!$E7/60 -> 628.33333
B8: 4 | C8: Kemasan | D8: Ikat/ 100 Lembar | E8: 23500 | F8: =CR!$E8/100/3 -> 78.333333
B9: 5 | C9: Saus Sambal Delmonte | D9: Pack/ 125 Sachet | E9: 22500 | F9: =CR!$E9/125 -> 180
B10: 6 | C10: Kantong Plastik | D10: Pack/ 50 Lembar | E10: 7000 | F10: =CR!$E10/50/3 -> 46.666667
B11: 7 | C11: Gas 3 kg | D11: 3 Kg | E11: 23000 | F11: =E11/150 -> 153.33333
E12: Total Cost/ Tusuk | F12: =SUM(F5:F11) -> 3526.6667
E13: Pendapatan/ Tusuk | F13: 4000
E14: Margin/ Tusuk | F14: =F13-F12 -> 473.33333

Sheet BKS
B2: BAKSO
B4: NO | C4: INGREDIENTS | D4: UOM | E4: BIAYA/UOM | F4: TOTAL COST/TUSUK
B5: 1 | C5: Bakso | D5: Pack/ 50 Pcs | E5: 24000 | F5: =BKS!$E5/10 -> 2400
B6: 2 | C6: Tepung Bumbu | D6: Pack | E6: 23500 | F6: =CR!$E6*0 -> 0
B7: 3 | C7: Minyak Goreng | D7: Pouch/ 2 Liter | E7: 37700 | F7: =BKS!$E7/60 -> 628.33333
B8: 4 | C8: Kemasan | D8: Ikat/ 95 Lembar | E8: 23500 | F8: =BKS!$E8/95/3 -> 82.45614
B9: 5 | C9: Saus Sambal Delmonte | D9: Pack/ 125 Sachet | E9: 22500 | F9: =BKS!$E9/125 -> 180
B10: 6 | C10: Kantong Plastik | D10: Pack/ 50 Lembar | E10: 7000 | F10: =BKS!$E10/50 -> 140
B11: 7 | C11: Gas 3 kg | D11: 3 Kg | E11: 23000 | F11: =E11/150 -> 153.33333
E12: Total Cost/ Tusuk | F12: =SUM(F5:F11) -> 3584.1228
E13: Pendapatan/ Tusuk | F13: 4000
E14: Margin/ Tusuk | F14: =F13-F12 -> 415.87719

Sheet CS
B2: CHIKEN STRIP
B4: NO | C4: INGREDIENTS | D4: UOM | E4: BIAYA/UOM | F4: TOTAL COST/TUSUK
B5: 1 | C5: Chiken Strip | D5: Pack/ 60 Pcs | E5: 59800 | F5: =CS!$E5/30 -> 1993.3333
B6: 2 | C6: Tepung Bumbu | D6: Pack | E6: 23500 | F6: =CS!$E6/1400*20 -> 335.71429
B7: 3 | C7: Minyak Goreng | D7: Pouch/ 2 Liter | E7: 37700 | F7: =CS!$E7/60 -> 628.33333
B8: 4 | C8: Kemasan | D8: Ikat/ 100 Lembar | E8: 23500 | F8: =CS!$E8/100/3 -> 78.333333
B9: 5 | C9: Saus Sambal Delmonte | D9: Pack/ 125 Sachet | E9: 22500 | F9: =CS!$E9/125 -> 180
B10: 6 | C10: Kantong Plastik | D10: Pack/ 50 Lembar | E10: 7000 | F10: =CS!$E10/50/2 -> 70
B11: 7 | C11: Gas 3 kg | D11: 3 Kg | E11: 23000 | F11: =E11/150 -> 153.33333
E12: Total Cost/ Tusuk | F12: =SUM(F5:F11) -> 3439.0476
E13: Pendapatan/ Tusuk | F13: 4000
E14: Margin/ Tusuk | F14: =F13-F12 -> 560.95238

Sheet CHICKEN BUN
B2: CHICKEN BUN
B4: NO | C4: INGREDIENTS | D4: UOM | E4: BIAYA/UOM | F4: TOTAL COST/KEMASAN | G4: KETERANGAN
B5: 1 | C5: Roti Bun | D5: 1 Pcs | E5: 2000 | F5: ='CHICKEN BUN'!$E5 -> 2000
B6: 2 | C6: Ayam Goreng - Sayap | D6: 1 Potong | E6: 8000 | F6: ='CHICKEN BUN'!$E6/3 -> 2666.6667 | G6: 1 Sayap dibagi 3
B7: 3 | C7: Mentega | D7: Pouch/ 200 Gram | E7: 10000 | F7: ='CHICKEN BUN'!$E7/200*3 -> 150
B8: 4 | C8: Sauce BBQ | D8: Sachet/ 20 Gram | E8: 800 | F8: ='CHICKEN BUN'!$E8/3 -> 266.66667
B9: 5 | C9: Saus Sambal Delmonte | D9: Pack/ 125 Sachet | E9: 22500 | F9: ='CHICKEN BUN'!$E9/125/3 -> 60
B10: 6 | C10: Mayonaise | D10: Pouch/ 900 Gram | E10: 35000 | F10: ='CHICKEN BUN'!$E10/900*8 -> 311.11111
B11: 7 | C11: Oregano | D11: 20 Gram | E11: 8000 | F11: ='CHICKEN BUN'!$E11/20*0.3 -> 120 | G11: 0.3 Gram
B12: 8 | C12: Kantong Plastik | D12: Pack/ 50 Lembar | E12: 7000 | F12: ='CHICKEN BUN'!$E12/50 -> 140
B13: 9 | C13: Box Serbaguna | D13: Box Burger, Box CB | E13: 85000 | F13: ='CHICKEN BUN'!$E13/100 -> 850
B14: 10 | C14: Gas 3 Kg | D14: 3 Kg | E14: 23000 | F14: =E14/150 -> 153.33333
E15: Total Cost/ Kemasan | F15: =SUM(F5:F14) -> 6717.7778
E16: Pendapatan/ Kemasan | F16: 10000
E17: Margin/ Kemasan | F17: =F16-F15 -> 3282.2222

Sheet KULIT
B2: KULIT CRISPY
B4: NO | C4: INGREDIENTS | D4: UOM | E4: BIAYA/UOM | F4: TOTAL COST/KEMASAN | G4: KETERANGAN
B5: 1 | C5: Kulit | D5: Pack/ 500 Gram | E5: 20000 | F5: =KULIT!$E5/10 -> 2000 | G5: 10 kantong
B6: 2 | C6: Tepung Bumbu | D6: Pack | E6: 23500 | F6: =CS!$E6/1400*25 -> 419.64286 | G6: 25 Gram | K6: 10 | L6: 1
B7: 3 | C7: Minyak Goreng | D7: Pouch/ 2 Liter | E7: 37700 | F7: =CS!$E7/60 -> 628.33333 | K7: =K6*L7 -> 100 | L7: 10
B8: 4 | C8: Kemasan Kulit | D8: Ikat/ 100 Lembar | E8: 15000 | F8: =KULIT!$E8/100 -> 150
B9: 5 | C9: Saus Sambal Delmonte | D9: Pack/ 125 Sachet | E9: 22500 | F9: =KULIT!$E9/125 -> 180
B10: 6 | C10: Kantong Plastik | D10: Pack/ 50 Lembar | E10: 7000 | F10: =KULIT!$E10/50 -> 140
B11: 7 | C11: Gas 3 kg | D11: 3 Kg | E11: 23000 | F11: =E11/150 -> 153.33333
E12: Total Cost/ Kemasan | F12: =SUM(F5:F11) -> 3671.3095
E13: Pendapatan/ Kemasan | F13: 5000
E14: Margin/ Kemasan | F14: =F13-F12 -> 1328.6905

Sheet BURGER
B2: BURGER
B4: NO | C4: INGREDIENTS | D4: UOM | E4: BIAYA/UOM | F4: TOTAL COST/KEMASAN | G4: KETERANGAN
B5: 1 | C5: Roti | D5: Pack/ 2 Pcs | E5: 2600 | F5: =BURGER!$E5 -> 2600
B6: 2 | C6: Chicken Patty | D6: Pack/ 10 Pcs | E6: 4500 | F6: =BURGER!$E6 -> 4500
B7: 3 | C7: Mayonaise | D7: Pouch/ 900 Gram | E7: 35000 | F7: =BURGER!$E7/45 -> 777.77778 | G7: 45 Gram
B8: 4 | C8: Sayuran (Tomat, Salada, Timun) | E8: 1100 | F8: 1000 | G8: Tomat 1 Slices, Salada 1 Lembar, Timun 2 Slices
B9: 5 | C9: Mentega | E9: 7000 | F9: =BURGER!$E9/50 -> 140
B10: 6 | C10: Saus | D10: 1 Pack/ isi 125 pcs | E10: 23500 | F10: =BURGER!$E10/125 -> 188
B11: 6 | C11: Box Burger | D11: Pack/ 100 Pcs | E11: 70000 | F11: =BURGER!$E11/100 -> 700
B12: 7 | C12: Kantong Plastik | D12: Pack/ 50 Lembar | E12: 7000 | F12: =BURGER!$E12/50 -> 140
B13: 8 | C13: Gas 3 kg | D13: 3 Kg | E13: 23000 | F13: =E13/150 -> 153.33333
E14: Total Cost/ Kemasan | F14: =SUM(F5:F13) -> 10199.111
E15: Pendapatan/ Kemasan | F15: 12000
E16: Margin/ Kemasan | F16: =F15-F14 -> 1800.8889

Sheet KENTANG
B2: KENTANG
B4: NO | C4: INGREDIENTS | D4: UOM | E4: BIAYA/UOM | F4: TOTAL COST/KEMASAN | G4: KETERANGAN | H4: Column1
B5: 1 | C5: Kentang Simplot | D5: Pack/ 2.72 Kg | E5: 113000 | F5: =KENTANG!$E5/2720*120 -> 4985.2941 | G5: 120 Gram | H5: =2720/120 -> 22.666667
B6: 2 | C6: Minyak Goreng | D6: Pouch/ 2 Liter | E6: 37700 | F6: =KENTANG!$E6/80 -> 471.25 | H6: =2720/120 -> 22.666667
B7: 3 | C7: Box Kentang | D7: Pack/ 200 Pcs | E7: 119800 | F7: =KENTANG!$E7/200 -> 599 | H7: =2720/120 -> 22.666667
B8: 4 | C8: Saus Sambal Delmonte | D8: Pack/ 125 Sachet | E8: 22500 | F8: =KENTANG!$E8/125*2 -> 360 | H8: =2720/120 -> 22.666667
B9: 5 | C9: Kantong Plastik | D9: Pack/ 50 Lembar | E9: 7000 | F9: =KENTANG!$E9/50 -> 140 | H9: =2720/120 -> 22.666667
B10: 6 | C10: Gas 3 kg | D10: 3 Kg | E10: 23000 | F10: =E10/150 -> 153.33333 | H10: =2720/120 -> 22.666667
E11: Total Cost/ Kemasan | F11: =SUM(F5:F10) -> 6708.8775 | H11: =2720/120 -> 22.666667
E12: Pendapatan/ Kemasan | F12: 8000 | H12: =2720/120 -> 22.666667
E13: Margin/ Kemasan | F13: =F12-F11 -> 1291.1225 | H13: =2720/120 -> 22.666667

Sheet GEPREK
B2: SAMBAL GEPREK
B4: NO | C4: INGREDIENTS | D4: UOM | E4: BIAYA/UOM | F4: TOTAL COST/CUP | G4: KETERANGAN
B5: 1 | C5: Sambal Geprek | D5: Pack/ 500 Gr | E5: 50000 | F5: =GEPREK!$E5/25 -> 2000 | G5: 25 CUP
B6: 2 | C6: Minyak Goreng | D6: Pouch/ 2 Liter | E6: 37700 | F6: =GEPREK!$E6/2000*12.22 -> 230.347 | G6: 12.22 ml
B7: 3 | C7: Sauce Cup | D7: Pack/ 50 Pcs | E7: 12600 | F7: =GEPREK!$E7/50 -> 252
E8: Total Cost/ Cup | F8: =SUM(F5:F7) -> 2482.347
E9: Pendapatan/ Cup | F9: 4000
E10: Margin/ Cup | F10: =F9-F8 -> 1517.653

Sheet BULDAK
B2: SAOS BULDAK
B4: NO | C4: INGREDIENTS | D4: UOM | E4: BIAYA/UOM | F4: TOTAL COST/CUP | G4: KETERANGAN
B5: 1 | C5: Saos Buldak | D5: Pack/ 500 Gr | E5: 36800 | F5: =BULDAK!$E5/25 -> 1472 | G5: 25 CUP
B6: 2 | C6: Sauce Cup | D6: Pack/ 50 Pcs | E6: 12600 | F6: =BULDAK!$E6/50 -> 252
E7: Total Cost/ Cup | F7: =SUM(F5:F6) -> 1724
E8: Pendapatan/ Cup | F8: 3000
E9: Margin/ Cup | F9: =F8-F7 -> 1276

Sheet MENTAI
B2: SAOS MENTAI
B4: NO | C4: INGREDIENTS | D4: UOM | E4: BIAYA/UOM | F4: TOTAL COST/CUP | G4: Column1
B5: 1 | C5: Saus Keju Mentai | D5: Pack/ 500 Gr | E5: 25600 | F5: =MENTAI!$E5/25 -> 1024 | G5: 25 CUP
B6: 2 | C6: Sauce Cup | D6: Pack/ 50 Pcs | E6: 12600 | F6: =MENTAI!$E6/50 -> 252
E7: Total Cost/ Cup | F7: =SUM(F5:F6) -> 1276
E8: Pendapatan/ Cup | F8: 2000
E9: Margin/ Cup | F9: =F8-F7 -> 724

Sheet SADAS
B2: SAOS SADAS
B4: NO | C4: INGREDIENTS | D4: UOM | E4: BIAYA/UOM | F4: TOTAL COST/CUP | G4: Column1
B5: 1 | C5: Saus Sadas | D5: Pack/ 500 Gr | E5: 24500 | F5: =SADAS!$E5/25 -> 980 | G5: 25 CUP
B6: 2 | C6: Sauce Cup | D6: Pack/ 28 Pcs | E6: 12600 | F6: =SADAS!$E6/50 -> 252
E7: Total Cost/ Cup | F7: =SUM(F5:F6) -> 1232
E8: Pendapatan/ Cup | F8: 3000
E9: Margin/ Cup | F9: =F8-F7 -> 1768

Sheet SAMBAL HITAM
B2: SAMBAL HITAM
B4: NO | C4: INGREDIENTS | D4: UOM | E4: BIAYA/UOM | F4: TOTAL COST/CUP | G4: KETERANGAN
B5: 1 | C5: Sambal Sambal Hitam | D5: Pack/ 500 Gr | E5: 50500 | F5: ='SAMBAL HITAM'!$E5/25 -> 2020 | G5: 25 CUP
B6: 2 | C6: Sauce Cup | D6: Pack/ 50 Pcs | E6: 12600 | F6: ='SAMBAL HITAM'!$E6/50 -> 252
E7: Total Cost/ Cup | F7: =SUM(F5:F6) -> 2272
E8: Pendapatan/ Cup | F8: 4000
E9: Margin/ Cup | F9: =F8-F7 -> 1728

Sheet SAMBAL IJO
B2: SAMBAL IJO
B4: NO | C4: INGREDIENTS | D4: UOM | E4: BIAYA/UOM | F4: TOTAL COST/CUP | G4: KETERANGAN
B5: 1 | C5: Sambal Ijo | D5: Pack/ 500 Gr | E5: 50000 | F5: ='SAMBAL IJO'!$E5/25 -> 2000 | G5: 25 CUP
B6: 2 | C6: Minyak Goreng | D6: Pouch/ 2 Liter | E6: 37000 | F6: ='SAMBAL IJO'!$E6/2000*12.22 -> 226.07 | G6: 12.22 ml
B7: 3 | C7: Sauce Cup | D7: Pack/ 50 Pcs | E7: 12600 | F7: ='SAMBAL IJO'!$E7/50 -> 252
E8: Total Cost/ Cup | F8: =SUM(F5:F7) -> 2478.07
E9: Pendapatan/ Cup | F9: 4000
E10: Margin/ Cup | F10: =F9-F8 -> 1521.93

Sheet KATSU
B2: CHICKEN KATSU 650 ML
B4: NO | C4: INGREDIENTS | D4: UOM | E4: BIAYA/UOM | F4: TOTAL COST
B5: 1 | C5: Chicken Katsu | D5: 1 Pcs / 90 Gr | E5: 4500 | F5: =KATSU!$E5 -> 4500
B6: 2 | C6: Minyak Goreng | D6: 1 Pouch | E6: 37700 | F6: =KATSU!$E6*(22/2000) -> 414.7
B7: 3 | C7: Gas | D7: 3 kg | E7: 23000 | F7: =KATSU!$E7/153 -> 150.3268
B8: 6 | C8: Saus Sambal Sabana | D8: 1 Pack/125 Pcs | E8: 23500 | F8: =KATSU!$E8/125*2 -> 376
B9: 10 | C9: Plastik Kecil | D9: 1 Pcs | E9: 7000 | F9: =KATSU!$E9/50 -> 140
B10: 11 | C10: Kemasan Ayam | D10: 1 Ikat/ 100pcs | E10: 23500 | F10: =KATSU!$E10/100 -> 235
E11: Total Cost/ Kemasan | F11: =SUM(F5:F10) -> 5816.0268
E12: Pendapatan/ Kemasan | F12: 8000
E13: Margin/ Kemasan | F13: =F12-F11 -> 2183.9732

Sheet RICE BOWL 650ML
B3: RICE BOWL SAMBAL GEPREK 650 ML
B5: NO | C5: INGREDIENTS | D5: UOM | E5: BIAYA/UOM | F5: TOTAL COST
B6: 1 | C6: Ayam Sayap/ Paha Bawah | D6: 1 Potong | E6: 5845 | F6: ='RICE BOWL 650ML'!$E6 -> 5845
B7: 2 | C7: Nasi | D7: 160 Gr | E7: 1502 | F7: ='RICE BOWL 650ML'!$E7 -> 1502
B8: 3 | C8: Sambal Geprek | D8: 30 Ml | E8: 3000 | F8: ='RICE BOWL 650ML'!$E8/35*30 -> 2571.4286
B9: 4 | C9: Sendok Plastik | D9: 1 Pcs | E9: 6000 | F9: ='RICE BOWL 650ML'!$E9/25 -> 240
B10: 5 | C10: Plastik Kecil Sabana | D10: 1 Pcs | E10: 7000 | F10: ='RICE BOWL 650ML'!$E10/50 -> 140
B11: 6 | C11: Paper Bowl 650 Ml | D11: 1 Pcs | E11: 41250 | F11: ='RICE BOWL 650ML'!$E11/25 -> 1650
B12: 7 | C12: Timun | D12: 2 Slice | E12: 8000 | F12: 375
E13: Total Cost/ Kemasan | F13: =SUM(F6:F12) -> 12323.429
E14: Pendapatan/ Kemasan | F14: 15000
E15: Margin/ Kemasan | F15: =F14-F13 -> 2676.5714
B17: RICE BOWL BBQ SAUCE 650 ML
B19: NO | C19: INGREDIENTS | D19: UOM | E19: BIAYA/UOM | F19: TOTAL COST
B20: 1 | C20: Ayam Sayap/ Paha Bawah | D20: 1 Potong | E20: 5845 | F20: ='RICE BOWL 650ML'!$E20 -> 5845
B21: 2 | C21: Nasi | D21: 160 Gr | E21: 1502 | F21: ='RICE BOWL 650ML'!$E21 -> 1502
B22: 3 | C22: BBQ Sauce | D22: 2 Pcs | E22: 800 | F22: ='RICE BOWL 650ML'!$E22*2 -> 1600
B23: 4 | C23: Saus Sambal | D23: 2 Pcs | E23: 22500 | F23: ='RICE BOWL 650ML'!$E23/125*2 -> 360
B24: 5 | C24: Sendok Plastik | D24: 1 Pcs | E24: 6000 | F24: ='RICE BOWL 650ML'!$E24/25 -> 240
B25: 6 | C25: Plastik Kecil Sabana | D25: 1 Pcs | E25: 7000 | F25: ='RICE BOWL 650ML'!$E25/50 -> 140
B26: 7 | C26: Paper Bowl 650 Ml | D26: 1 Pcs | E26: 41250 | F26: ='RICE BOWL 650ML'!$E26/25 -> 1650
B27: 8 | C27: Timun | D27: 2 Slice | E27: 8000 | F27: 375
B28: 9 | C28: Oregano | D28: 0.03 Gr | E28: 8000 | F28: ='RICE BOWL 650ML'!$E28/25*0.03 -> 9.6
E29: Total Cost/ Kemasan | F29: =SUM(F20:F28) -> 11721.6
E30: Pendapatan/ Kemasan | F30: 15000
E31: Margin/ Kemasan | F31: =F30-F29 -> 3278.4
B33: RICE BOWL KATSU 650 ML
B35: NO | C35: INGREDIENTS | D35: UOM | E35: BIAYA/UOM | F35: TOTAL COST
B36: 1 | C36: Chicken Katsu | D36: 1 Pcs / 90 Gr | E36: 4500 | F36: ='RICE BOWL 650ML'!$E36 -> 4500
B37: 2 | C37: Minyak Goreng | D37: 1 Pouch | E37: 37700 | F37: ='RICE BOWL 650ML'!$E37*(22/2000) -> 414.7
B38: 3 | C38: Gas | D38: 3 kg | E38: 23000 | F38: ='RICE BOWL 650ML'!$E38/153 -> 150.3268
B39: 4 | C39: Nasi | D39: 180 gr | E39: 1502 | F39: ='RICE BOWL 650ML'!$E39*(180/160) -> 1689.75
B40: 5 | C40: Saus Keju Mentai | D40: Pouch/500gram | E40: 25600 | F40: ='RICE BOWL 650ML'!$E40*(18/500) -> 921.6
B41: 6 | C41: Saus Sambal Sabana | D41: 1 Pack/125 Pcs | E41: 23500 | F41: ='RICE BOWL 650ML'!$E41/125 -> 188
B42: 7 | C42: Timun | D42: 2 Slice | E42: 8000 | F42: ='RICE BOWL 650ML'!$E42/850*30 -> 282.35294
B43: 8 | C43: Selada | D43: 1 Lembar | E43: 5000 | F43: =('RICE BOWL 650ML'!$E43/200)*10 -> 250
B44: 9 | C44: Sendok Gapru | D44: 1 Pcs | E44: 10000 | F44: ='RICE BOWL 650ML'!$E44/50 -> 200
B45: 10 | C45: Plastik Kecil | D45: 1 Pcs | E45: 7000 | F45: ='RICE BOWL 650ML'!$E45/50 -> 140
B46: 11 | C46: Paper Bowl 650ml | D46: 1 Pcs | E46: 41250 | F46: ='RICE BOWL 650ML'!$E46/25 -> 1650
E47: Total Cost/ Kemasan | F47: =SUM(F36:F46) -> 10386.73
...

Sheet RICE BOWL 500ML
B3: RICE BOWL SAMBAL GEPREK 500 ML
B5: NO | C5: INGREDIENTS | D5: UOM | E5: BIAYA/UOM | F5: TOTAL COST
B6: 1 | C6: Ayam Sayap/ Paha Bawah | D6: 0.75 Gr | E6: 5845 | F6: ='RICE BOWL 500ML'!$E6*0.75 -> 4383.75
B7: 2 | C7: Nasi | D7: 140 Gr | E7: 1502 | F7: ='RICE BOWL 500ML'!$E7/160*140 -> 1314.25
B8: 3 | C8: Sambal Geprek | D8: 20 Ml | E8: 3000 | F8: ='RICE BOWL 500ML'!$E8/35*20 -> 1714.2857
B9: 4 | C9: Sendok Plastik | D9: 1 Pcs | E9: 6000 | F9: ='RICE BOWL 500ML'!$E9/25 -> 240
B10: 5 | C10: Plastik Kecil Sabana | D10: 1 Pcs | E10: 7000 | F10: ='RICE BOWL 500ML'!$E10/50 -> 140
B11: 6 | C11: Paper Bowl 500 Ml | D11: 1 Pcs | E11: 38750 | F11: ='RICE BOWL 500ML'!$E11/25 -> 1550
B12: 7 | C12: Timun | D12: 2 Slice | E12: 8000 | F12: 375
E13: Total Cost/ Kemasan | F13: =SUM(F6:F12) -> 9717.2857
E14: Pendapatan/ Kemasan | F14: 12000
E15: Margin/ Kemasan | F15: =F14-F13 -> 2282.7143
B17: RICE BOWL BBQ SAUCE 500 ML
B19: NO | C19: INGREDIENTS | D19: UOM | E19: BIAYA/UOM | F19: TOTAL COST
B20: 1 | C20: Ayam Sayap/ Paha Bawah | D20: 0.75 Gr | E20: 5845 | F20: ='RICE BOWL 500ML'!$E20*0.75 -> 4383.75
B21: 2 | C21: Nasi | D21: 140 Gr | E21: 1502 | F21: ='RICE BOWL 500ML'!$E21/160*140 -> 1314.25
B22: 3 | C22: BBQ Sauce | D22: 1 Pcs | E22: 800 | F22: ='RICE BOWL 500ML'!$E22 -> 800
B23: 4 | C23: Saus Sambal | D23: 1 PCS | E23: 22500 | F23: ='RICE BOWL 500ML'!$E23/125 -> 180
B24: 5 | C24: Sendok Plastik | D24: 1 Pcs | E24: 6000 | F24: ='RICE BOWL 500ML'!$E24/25 -> 240
B25: 6 | C25: Plastik Kecil Sabana | D25: 1 Pcs | E25: 7000 | F25: ='RICE BOWL 500ML'!$E25/50 -> 140
B26: 7 | C26: Paper Bowl 500 Ml | D26: 1 Pcs | E26: 38750 | F26: ='RICE BOWL 500ML'!$E26/25 -> 1550
B27: 8 | C27: Timun | D27: 2 Slice | E27: 8000 | F27: 375
B28: 9 | C28: Oregano | D28: 0.03 Gr | E28: 8000 | F28: ='RICE BOWL 500ML'!$E28/25*0.03 -> 9.6
E29: Total Cost/ Kemasan | F29: =SUM(F20:F28) -> 8992.6
E30: Pendapatan/ Kemasan | F30: 12000
E31: Margin/ Kemasan | F31: =F30-F29 -> 3007.4

Sheet SIMULASI
B3: NAMA PRODUK | C3: QTY | D3: HARI | E3: MODAL | F3: PENDAPATAN | G3: PROFIT | H3: TOTAL PROFIT | I3: TOTAL MODAL | J3: TOTAL PENDAPATAN
B4: AYAM FRIED CHICKEN | C4: 12 | D4: 30 | E4: ='AYAM REGULER'!G12 -> 63710.833 | F4: 89000 | G4: ='AYAM REGULER'!G14 -> 25289.167 | H4: =C4*D4*G4 -> 9104100 | I4: =C4*D4*E4 -> 22935900 | J4: =C4*D4*F4 -> 32040000
B5: NASI | C5: 10 | D5: 30 | E5: =NASI!$G5 -> 1333.3333 | F5: 5000 | G5: =NASI!G10 -> 2286.6667 | H5: =C5*D5*G5 -> 686000 | I5: =C5*D5*E5 -> 400000 | J5: =C5*D5*F5 -> 1500000
B6: CHICKEN ROLL | C6: 10 | D6: 30 | E6: =CR!F12 -> 3526.6667 | F6: 4000 | G6: =F6-E6 -> 473.33333 | H6: =C6*D6*G6 -> 142000 | I6: =C6*D6*E6 -> 1058000 | J6: =C6*D6*F6 -> 1200000
B7: BAKSO | C7: 10 | D7: 30 | E7: =BKS!F12 -> 3584.1228 | F7: 4000 | G7: =F7-E7 -> 415.87719 | H7: =C7*D7*G7 -> 124763.16 | I7: =C7*D7*E7 -> 1075236.8 | J7: =C7*D7*F7 -> 1200000
B8: CHICKEN STRIP | C8: 10 | D8: 30 | E8: =CS!F12 -> 3439.0476 | F8: 4000 | G8: =F8-E8 -> 560.95238 | H8: =C8*D8*G8 -> 168285.71 | I8: =C8*D8*E8 -> 1031714.3 | J8: =C8*D8*F8 -> 1200000
B9: KULIT CRISPY | C9: 10 | D9: 30 | E9: =KULIT!$F9 -> 180 | F9: 5000 | G9: =F9-E9 -> 4820 | H9: =C9*D9*G9 -> 1446000 | I9: =C9*D9*E9 -> 54000 | J9: =C9*D9*F9 -> 1500000
B10: CHICKEN BUN | C10: 0 | D10: 30 | E10: ='CHICKEN BUN'!F15 -> 6717.7778 | F10: 10000 | G10: =F10-E10 -> 3282.2222 | H10: =C10*D10*G10 -> 0 | I10: =C10*D10*E10 -> 0 | J10: =C10*D10*F10 -> 0
B11: KENTANG GORENG | C11: 5 | D11: 30 | E11: ='CHICKEN BUN'!F15 -> 6717.7778 | F11: 8000 | G11: =F11-E11 -> 1282.2222 | H11: =C11*D11*G11 -> 192333.33 | I11: =C11*D11*E11 -> 1007666.7 | J11: =C11*D11*F11 -> 1200000
B12: BURGER | C12: 0 | D12: 30 | E12: =BURGER!F14 -> 10199.111 | F12: 12000 | G12: =F12-E12 -> 1800.8889 | H12: =C12*D12*G12 -> 0 | I12: =C12*D12*E12 -> 0 | J12: =C12*D12*F12 -> 0
B13: KATSU | C13: 10 | D13: 30 | G13: =KATSU!$F13 -> 2183.9732 | H13: =C13*D13*G13 -> 655191.96
B14: SAMBAL GEPREK | C14: 10 | D14: 30 | E14: =GEPREK!F8 -> 2482.347 | F14: 4000 | G14: 1605 | H14: =C14*D14*G14 -> 481500 | I14: =C14*D14*E14 -> 744704.1 | J14: =C14*D14*F14 -> 1200000
B15: SAOS BULDAK | C15: 0 | D15: 30 | E15: =BULDAK!F7 -> 1724 | F15: 3000 | H15: =C15*D15*G15 -> 0 | I15: =C15*D15*E15 -> 0 | J15: =C15*D15*F15 -> 0
B16: SAOS MENTAI | C16: 10 | D16: 30 | E16: =MENTAI!F7 -> 1276 | F16: 2000 | G16: 724 | H16: =C16*D16*G16 -> 217200 | I16: =C16*D16*E16 -> 382800 | J16: =C16*D16*F16 -> 600000
B17: SAOS SADAS | C17: 0 | D17: 30 | E17: =SADAS!F7 -> 1232 | F17: 3000 | G17: =F17-E17 -> 1768 | H17: =C17*D17*G17 -> 0 | I17: =C17*D17*E17 -> 0 | J17: =C17*D17*F17 -> 0
B18: SAMBAL HITAM | C18: 0 | D18: 30 | E18: ='SAMBAL HITAM'!F7 -> 2272 | F18: 4000 | G18: =F18-E18 -> 1728 | H18: =C18*D18*G18 -> 0 | I18: =C18*D18*E18 -> 0 | J18: =C18*D18*F18 -> 0
B19: SAMBAL IJO | C19: 10 | D19: 30 | E19: ='SAMBAL IJO'!F8 -> 2478.07 | F19: 4000 | G19: 1739 | H19: =C19*D19*G19 -> 521700 | I19: =C19*D19*E19 -> 743421 | J19: =C19*D19*F19 -> 1200000
B20: LISTRIK | C20: 1 | D20: 1 | E20: 200000 | H20: 250000 | I20: =C20*D20*E20 -> 200000
B21: KARYAWAN | C21: 1 | D21: 1 | E21: 1500000 | H21: 1500000
B22: KIOS | C22: 1 | D22: 1 | E22: 1500000 | H22: 1500000
H23: =SUM(H4:H19)-H20-H21-H22 -> 10489074 | I23: =SUM(I4:I19) -> 29433443 | J23: =SUM(J4:J19) -> 42840000
